Workbook

Sheet Start here
A1: Debt snowball and avalanche planner
A3: How to use it
A4: 1. On the Debts tab, choose Snowball (smallest balance first) or Avalanche (highest rate first).
A5: 2. Type how much extra you can pay each month on top of your minimums.
A6: 3. List up to six debts: name, balance, yearly interest rate and minimum payment.
A7: 4. Read the results: payoff order, the month each debt is cleared, total months and total interest.
A8: 5. Switch the method to compare. The Schedule tab shows every month in detail.
A10: This is an estimate using simple monthly interest. Your lender's numbers will differ slightly.
A11: Needs Google Sheets, or Excel 2019 / Microsoft 365 (it uses the MINIFS function).
A13: Yellow cells are for you to type in. White cells calculate automatically, so leave them alone.
A14: The example numbers only show the format. Replace them with your own.
A16: Step-by-step guide: https://guidelark.com/blog/debt-snowball-spreadsheet/
A17: Free to use and share. General information, not financial advice.

Sheet Debts
A1: Debt payoff planner
A3: Method | B3: Snowball | C3: Snowball = smallest balance first. Avalanche = highest interest rate first.
A4: Extra payment each month | B4: 100 | C4: On top of all your minimum payments.
A6: Debt | B6: Balance | C6: Interest rate (APR) | D6: Minimum payment | E6: Payoff order | F6: Paid off in month
A7: Store card | B7: 900 | C7: 0.15 | D7: 30 | E7: =IF(N(B7)>0,IF($B$3="Avalanche",COUNTIFS($B$7:$B$12,">0",$C$7:$C$12,">"&N(C7))+COUNTIFS($C$7:C7,N(C7),$B$7:B7,">0"),COUNTIFS($B$7:$B$12,">0",$B$7:$B$12,"<"&B7)+COUNTIFS($B$7:B7,B7)),"") -> 1 | F7: =IF(N(B7)>0,IF(COUNTIF(Schedule!AC$5:AC$124,">0.005")>=120,"Over 10 years",COUNTIF(Schedule!AC$5:AC$124,">0.005")+1),"") -> 8
A8: Car loan | B8: 2000 | C8: 0.08 | D8: 60 | E8: =IF(N(B8)>0,IF($B$3="Avalanche",COUNTIFS($B$7:$B$12,">0",$C$7:$C$12,">"&N(C8))+COUNTIFS($C$7:C8,N(C8),$B$7:B8,">0"),COUNTIFS($B$7:$B$12,">0",$B$7:$B$12,"<"&B8)+COUNTIFS($B$7:B8,B8)),"") -> 2 | F8: =IF(N(B8)>0,IF(COUNTIF(Schedule!AD$5:AD$124,">0.005")>=120,"Over 10 years",COUNTIF(Schedule!AD$5:AD$124,">0.005")+1),"") -> 17
A9: Credit card | B9: 3200 | C9: 0.26 | D9: 96 | E9: =IF(N(B9)>0,IF($B$3="Avalanche",COUNTIFS($B$7:$B$12,">0",$C$7:$C$12,">"&N(C9))+COUNTIFS($C$7:C9,N(C9),$B$7:B9,">0"),COUNTIFS($B$7:$B$12,">0",$B$7:$B$12,"<"&B9)+COUNTIFS($B$7:B9,B9)),"") -> 3 | F9: =IF(N(B9)>0,IF(COUNTIF(Schedule!AE$5:AE$124,">0.005")>=120,"Over 10 years",COUNTIF(Schedule!AE$5:AE$124,">0.005")+1),"") -> 28
E10: =IF(N(B10)>0,IF($B$3="Avalanche",COUNTIFS($B$7:$B$12,">0",$C$7:$C$12,">"&N(C10))+COUNTIFS($C$7:C10,N(C10),$B$7:B10,">0"),COUNTIFS($B$7:$B$12,">0",$B$7:$B$12,"<"&B10)+COUNTIFS($B$7:B10,B10)),"") | F10: =IF(N(B10)>0,IF(COUNTIF(Schedule!AF$5:AF$124,">0.005")>=120,"Over 10 years",COUNTIF(Schedule!AF$5:AF$124,">0.005")+1),"")
E11: =IF(N(B11)>0,IF($B$3="Avalanche",COUNTIFS($B$7:$B$12,">0",$C$7:$C$12,">"&N(C11))+COUNTIFS($C$7:C11,N(C11),$B$7:B11,">0"),COUNTIFS($B$7:$B$12,">0",$B$7:$B$12,"<"&B11)+COUNTIFS($B$7:B11,B11)),"") | F11: =IF(N(B11)>0,IF(COUNTIF(Schedule!AG$5:AG$124,">0.005")>=120,"Over 10 years",COUNTIF(Schedule!AG$5:AG$124,">0.005")+1),"")
E12: =IF(N(B12)>0,IF($B$3="Avalanche",COUNTIFS($B$7:$B$12,">0",$C$7:$C$12,">"&N(C12))+COUNTIFS($C$7:C12,N(C12),$B$7:B12,">0"),COUNTIFS($B$7:$B$12,">0",$B$7:$B$12,"<"&B12)+COUNTIFS($B$7:B12,B12)),"") | F12: =IF(N(B12)>0,IF(COUNTIF(Schedule!AH$5:AH$124,">0.005")>=120,"Over 10 years",COUNTIF(Schedule!AH$5:AH$124,">0.005")+1),"")
A14: Total monthly payment | B14: =SUM(D7:D12)+B4 -> 286 | C14: Stays the same every month: cleared minimums roll into the next debt.
A15: Months until debt-free | B15: =IF(SUM(B7:B12)=0,"-",IF(COUNTIF(Schedule!AJ5:AJ124,">0.005")>=120,"Over 10 years",COUNTIF(Schedule!AJ5:AJ124,">0.005")+1)) -> 28
A16: Total interest paid | B16: =SUM(Schedule!AI5:AI124) -> 1632.5524
A17: Total paid | B17: =SUM(B7:B12)+B16 -> 7732.5524

Sheet Schedule
A1: Month-by-month schedule (calculated, no need to edit)
A2: Rows 1-3 hold each debt's minimum, rate and payoff order.
B3: =Debts!E7 -> 1 | C3: =Debts!E8 -> 2 | D3: =Debts!E9 -> 3 | E3: =Debts!E10 | F3: =Debts!E11 | G3: =Debts!E12
A4: Month | B4: Start 1 | C4: Start 2 | D4: Start 3 | E4: Start 4 | F4: Start 5 | G4: Start 6 | H4: Interest 1 | I4: Interest 2 | J4: Interest 3 | K4: Interest 4 | L4: Interest 5 | M4: Interest 6 | N4: Minimum 1 | O4: Minimum 2 | P4: Minimum 3 | Q4: Minimum 4 | R4: Minimum 5 | S4: Minimum 6 | T4: Total payment | U4: Extra pool | V4: Target | W4: Payment 1 | X4: Payment 2 | Y4: Payment 3 | Z4: Payment 4 | AA4: Payment 5 | AB4: Payment 6 | AC4: End 1 | AD4: End 2 | AE4: End 3 | AF4: End 4 | AG4: End 5 | AH4: End 6 | AI4: Interest total | AJ4: Balance left
A5: 1 | B5: =N(Debts!B7) -> 900 | C5: =N(Debts!B8) -> 2000 | D5: =N(Debts!B9) -> 3200 | E5: =N(Debts!B10) -> 0 | F5: =N(Debts!B11) -> 0 | G5: =N(Debts!B12) -> 0 | H5: =B5*N(Debts!C7)/12 -> 11.25 | I5: =C5*N(Debts!C8)/12 -> 13.333333 | J5: =D5*N(Debts!C9)/12 -> 69.333333 | K5: =E5*N(Debts!C10)/12 -> 0 | L5: =F5*N(Debts!C11)/12 -> 0 | M5: =G5*N(Debts!C12)/12 -> 0 | N5: =MIN(B5+H5,N(Debts!D7)) -> 30 | O5: =MIN(C5+I5,N(Debts!D8)) -> 60 | P5: =MIN(D5+J5,N(Debts!D9)) -> 96 | Q5: =MIN(E5+K5,N(Debts!D10)) -> 0 | R5: =MIN(F5+L5,N(Debts!D11)) -> 0 | S5: =MIN(G5+M5,N(Debts!D12)) -> 0 | T5: =Debts!$B$14 -> 286 | U5: =MAX(0,T5-SUM(N5:S5)) -> 100 | V5: =_xlfn.MINIFS($B$3:$G$3,B5:G5,">0.005") -> 1 | W5: =IF(B5<=0.005,0,MIN(B5+H5,N5+IF(B$3=$V5,$U5,0))) -> 130 | X5: =IF(C5<=0.005,0,MIN(C5+I5,O5+IF(C$3=$V5,$U5,0))) -> 60 | Y5: =IF(D5<=0.005,0,MIN(D5+J5,P5+IF(D$3=$V5,$U5,0))) -> 96 | Z5: =IF(E5<=0.005,0,MIN(E5+K5,Q5+IF(E$3=$V5,$U5,0))) -> 0 | AA5: =IF(F5<=0.005,0,MIN(F5+L5,R5+IF(F$3=$V5,$U5,0))) -> 0 | AB5: =IF(G5<=0.005,0,MIN(G5+M5,S5+IF(G$3=$V5,$U5,0))) -> 0 | AC5: =MAX(0,B5+H5-W5) -> 781.25 | AD5: =MAX(0,C5+I5-X5) -> 1953.3333 | AE5: =MAX(0,D5+J5-Y5) -> 3173.3333 | AF5: =MAX(0,E5+K5-Z5) -> 0 | AG5: =MAX(0,F5+L5-AA5) -> 0 | AH5: =MAX(0,G5+M5-AB5) -> 0 | AI5: =SUM(H5:M5) -> 93.916667 | AJ5: =SUM(AC5:AH5) -> 5907.9167
A6: 2 | B6: =AC5 -> 781.25 | C6: =AD5 -> 1953.3333 | D6: =AE5 -> 3173.3333 | E6: =AF5 -> 0 | F6: =AG5 -> 0 | G6: =AH5 -> 0 | H6: =B6*N(Debts!C7)/12 -> 9.765625 | I6: =C6*N(Debts!C8)/12 -> 13.022222 | J6: =D6*N(Debts!C9)/12 -> 68.755556 | K6: =E6*N(Debts!C10)/12 -> 0 | L6: =F6*N(Debts!C11)/12 -> 0 | M6: =G6*N(Debts!C12)/12 -> 0 | N6: =MIN(B6+H6,N(Debts!D7)) -> 30 | O6: =MIN(C6+I6,N(Debts!D8)) -> 60 | P6: =MIN(D6+J6,N(Debts!D9)) -> 96 | Q6: =MIN(E6+K6,N(Debts!D10)) -> 0 | R6: =MIN(F6+L6,N(Debts!D11)) -> 0 | S6: =MIN(G6+M6,N(Debts!D12)) -> 0 | T6: =Debts!$B$14 -> 286 | U6: =MAX(0,T6-SUM(N6:S6)) -> 100 | V6: =_xlfn.MINIFS($B$3:$G$3,B6:G6,">0.005") -> 1 | W6: =IF(B6<=0.005,0,MIN(B6+H6,N6+IF(B$3=$V6,$U6,0))) -> 130 | X6: =IF(C6<=0.005,0,MIN(C6+I6,O6+IF(C$3=$V6,$U6,0))) -> 60 | Y6: =IF(D6<=0.005,0,MIN(D6+J6,P6+IF(D$3=$V6,$U6,0))) -> 96 | Z6: =IF(E6<=0.005,0,MIN(E6+K6,Q6+IF(E$3=$V6,$U6,0))) -> 0 | AA6: =IF(F6<=0.005,0,MIN(F6+L6,R6+IF(F$3=$V6,$U6,0))) -> 0 | AB6: =IF(G6<=0.005,0,MIN(G6+M6,S6+IF(G$3=$V6,$U6,0))) -> 0 | AC6: =MAX(0,B6+H6-W6) -> 661.01562 | AD6: =MAX(0,C6+I6-X6) -> 1906.3556 | AE6: =MAX(0,D6+J6-Y6) -> 3146.0889 | AF6: =MAX(0,E6+K6-Z6) -> 0 | AG6: =MAX(0,F6+L6-AA6) -> 0 | AH6: =MAX(0,G6+M6-AB6) -> 0 | AI6: =SUM(H6:M6) -> 91.543403 | AJ6: =SUM(AC6:AH6) -> 5713.4601
A7: 3 | B7: =AC6 -> 661.01562 | C7: =AD6 -> 1906.3556 | D7: =AE6 -> 3146.0889 | E7: =AF6 -> 0 | F7: =AG6 -> 0 | G7: =AH6 -> 0 | H7: =B7*N(Debts!C7)/12 -> 8.2626953 | I7: =C7*N(Debts!C8)/12 -> 12.709037 | J7: =D7*N(Debts!C9)/12 -> 68.165259 | K7: =E7*N(Debts!C10)/12 -> 0 | L7: =F7*N(Debts!C11)/12 -> 0 | M7: =G7*N(Debts!C12)/12 -> 0 | N7: =MIN(B7+H7,N(Debts!D7)) -> 30 | O7: =MIN(C7+I7,N(Debts!D8)) -> 60 | P7: =MIN(D7+J7,N(Debts!D9)) -> 96 | Q7: =MIN(E7+K7,N(Debts!D10)) -> 0 | R7: =MIN(F7+L7,N(Debts!D11)) -> 0 | S7: =MIN(G7+M7,N(Debts!D12)) -> 0 | T7: =Debts!$B$14 -> 286 | U7: =MAX(0,T7-SUM(N7:S7)) -> 100 | V7: =_xlfn.MINIFS($B$3:$G$3,B7:G7,">0.005") -> 1 | W7: =IF(B7<=0.005,0,MIN(B7+H7,N7+IF(B$3=$V7,$U7,0))) -> 130 | X7: =IF(C7<=0.005,0,MIN(C7+I7,O7+IF(C$3=$V7,$U7,0))) -> 60 | Y7: =IF(D7<=0.005,0,MIN(D7+J7,P7+IF(D$3=$V7,$U7,0))) -> 96 | Z7: =IF(E7<=0.005,0,MIN(E7+K7,Q7+IF(E$3=$V7,$U7,0))) -> 0 | AA7: =IF(F7<=0.005,0,MIN(F7+L7,R7+IF(F$3=$V7,$U7,0))) -> 0 | AB7: =IF(G7<=0.005,0,MIN(G7+M7,S7+IF(G$3=$V7,$U7,0))) -> 0 | AC7: =MAX(0,B7+H7-W7) -> 539.27832 | AD7: =MAX(0,C7+I7-X7) -> 1859.0646 | AE7: =MAX(0,D7+J7-Y7) -> 3118.2541 | AF7: =MAX(0,E7+K7-Z7) -> 0 | AG7: =MAX(0,F7+L7-AA7) -> 0 | AH7: =MAX(0,G7+M7-AB7) -> 0 | AI7: =SUM(H7:M7) -> 89.136992 | AJ7: =SUM(AC7:AH7) -> 5516.5971
A8: 4 | B8: =AC7 -> 539.27832 | C8: =AD7 -> 1859.0646 | D8: =AE7 -> 3118.2541 | E8: =AF7 -> 0 | F8: =AG7 -> 0 | G8: =AH7 -> 0 | H8: =B8*N(Debts!C7)/12 -> 6.740979 | I8: =C8*N(Debts!C8)/12 -> 12.393764 | J8: =D8*N(Debts!C9)/12 -> 67.562173 | K8: =E8*N(Debts!C10)/12 -> 0 | L8: =F8*N(Debts!C11)/12 -> 0 | M8: =G8*N(Debts!C12)/12 -> 0 | N8: =MIN(B8+H8,N(Debts!D7)) -> 30 | O8: =MIN(C8+I8,N(Debts!D8)) -> 60 | P8: =MIN(D8+J8,N(Debts!D9)) -> 96 | Q8: =MIN(E8+K8,N(Debts!D10)) -> 0 | R8: =MIN(F8+L8,N(Debts!D11)) -> 0 | S8: =MIN(G8+M8,N(Debts!D12)) -> 0 | T8: =Debts!$B$14 -> 286 | U8: =MAX(0,T8-SUM(N8:S8)) -> 100 | V8: =_xlfn.MINIFS($B$3:$G$3,B8:G8,">0.005") -> 1 | W8: =IF(B8<=0.005,0,MIN(B8+H8,N8+IF(B$3=$V8,$U8,0))) -> 130 | X8: =IF(C8<=0.005,0,MIN(C8+I8,O8+IF(C$3=$V8,$U8,0))) -> 60 | Y8: =IF(D8<=0.005,0,MIN(D8+J8,P8+IF(D$3=$V8,$U8,0))) -> 96 | Z8: =IF(E8<=0.005,0,MIN(E8+K8,Q8+IF(E$3=$V8,$U8,0))) -> 0 | AA8: =IF(F8<=0.005,0,MIN(F8+L8,R8+IF(F$3=$V8,$U8,0))) -> 0 | AB8: =IF(G8<=0.005,0,MIN(G8+M8,S8+IF(G$3=$V8,$U8,0))) -> 0 | AC8: =MAX(0,B8+H8-W8) -> 416.0193 | AD8: =MAX(0,C8+I8-X8) -> 1811.4584 | AE8: =MAX(0,D8+J8-Y8) -> 3089.8163 | AF8: =MAX(0,E8+K8-Z8) -> 0 | AG8: =MAX(0,F8+L8-AA8) -> 0 | AH8: =MAX(0,G8+M8-AB8) -> 0 | AI8: =SUM(H8:M8) -> 86.696916 | AJ8: =SUM(AC8:AH8) -> 5317.294
A9: 5 | B9: =AC8 -> 416.0193 | C9: =AD8 -> 1811.4584 | D9: =AE8 -> 3089.8163 | E9: =AF8 -> 0 | F9: =AG8 -> 0 | G9: =AH8 -> 0 | H9: =B9*N(Debts!C7)/12 -> 5.2002412 | I9: =C9*N(Debts!C8)/12 -> 12.076389 | J9: =D9*N(Debts!C9)/12 -> 66.94602 | K9: =E9*N(Debts!C10)/12 -> 0 | L9: =F9*N(Debts!C11)/12 -> 0 | M9: =G9*N(Debts!C12)/12 -> 0 | N9: =MIN(B9+H9,N(Debts!D7)) -> 30 | O9: =MIN(C9+I9,N(Debts!D8)) -> 60 | P9: =MIN(D9+J9,N(Debts!D9)) -> 96 | Q9: =MIN(E9+K9,N(Debts!D10)) -> 0 | R9: =MIN(F9+L9,N(Debts!D11)) -> 0 | S9: =MIN(G9+M9,N(Debts!D12)) -> 0 | T9: =Debts!$B$14 -> 286 | U9: =MAX(0,T9-SUM(N9:S9)) -> 100 | V9: =_xlfn.MINIFS($B$3:$G$3,B9:G9,">0.005") -> 1 | W9: =IF(B9<=0.005,0,MIN(B9+H9,N9+IF(B$3=$V9,$U9,0))) -> 130 | X9: =IF(C9<=0.005,0,MIN(C9+I9,O9+IF(C$3=$V9,$U9,0))) -> 60 | Y9: =IF(D9<=0.005,0,MIN(D9+J9,P9+IF(D$3=$V9,$U9,0))) -> 96 | Z9: =IF(E9<=0.005,0,MIN(E9+K9,Q9+IF(E$3=$V9,$U9,0))) -> 0 | AA9: =IF(F9<=0.005,0,MIN(F9+L9,R9+IF(F$3=$V9,$U9,0))) -> 0 | AB9: =IF(G9<=0.005,0,MIN(G9+M9,S9+IF(G$3=$V9,$U9,0))) -> 0 | AC9: =MAX(0,B9+H9-W9) -> 291.21954 | AD9: =MAX(0,C9+I9-X9) -> 1763.5347 | AE9: =MAX(0,D9+J9-Y9) -> 3060.7623 | AF9: =MAX(0,E9+K9-Z9) -> 0 | AG9: =MAX(0,F9+L9-AA9) -> 0 | AH9: =MAX(0,G9+M9-AB9) -> 0 | AI9: =SUM(H9:M9) -> 84.222651 | AJ9: =SUM(AC9:AH9) -> 5115.5166
A10: 6 | B10: =AC9 -> 291.21954 | C10: =AD9 -> 1763.5347 | D10: =AE9 -> 3060.7623 | E10: =AF9 -> 0 | F10: =AG9 -> 0 | G10: =AH9 -> 0 | H10: =B10*N(Debts!C7)/12 -> 3.6402443 | I10: =C10*N(Debts!C8)/12 -> 11.756898 | J10: =D10*N(Debts!C9)/12 -> 66.316517 | K10: =E10*N(Debts!C10)/12 -> 0 | L10: =F10*N(Debts!C11)/12 -> 0 | M10: =G10*N(Debts!C12)/12 -> 0 | N10: =MIN(B10+H10,N(Debts!D7)) -> 30 | O10: =MIN(C10+I10,N(Debts!D8)) -> 60 | P10: =MIN(D10+J10,N(Debts!D9)) -> 96 | Q10: =MIN(E10+K10,N(Debts!D10)) -> 0 | R10: =MIN(F10+L10,N(Debts!D11)) -> 0 | S10: =MIN(G10+M10,N(Debts!D12)) -> 0 | T10: =Debts!$B$14 -> 286 | U10: =MAX(0,T10-SUM(N10:S10)) -> 100 | V10: =_xlfn.MINIFS($B$3:$G$3,B10:G10,">0.005") -> 1 | W10: =IF(B10<=0.005,0,MIN(B10+H10,N10+IF(B$3=$V10,$U10,0))) -> 130 | X10: =IF(C10<=0.005,0,MIN(C10+I10,O10+IF(C$3=$V10,$U10,0))) -> 60 | Y10: =IF(D10<=0.005,0,MIN(D10+J10,P10+IF(D$3=$V10,$U10,0))) -> 96 | Z10: =IF(E10<=0.005,0,MIN(E10+K10,Q10+IF(E$3=$V10,$U10,0))) -> 0 | AA10: =IF(F10<=0.005,0,MIN(F10+L10,R10+IF(F$3=$V10,$U10,0))) -> 0 | AB10: =IF(G10<=0.005,0,MIN(G10+M10,S10+IF(G$3=$V10,$U10,0))) -> 0 | AC10: =MAX(0,B10+H10-W10) -> 164.85978 | AD10: =MAX(0,C10+I10-X10) -> 1715.2916 | AE10: =MAX(0,D10+J10-Y10) -> 3031.0789 | AF10: =MAX(0,E10+K10-Z10) -> 0 | AG10: =MAX(0,F10+L10-AA10) -> 0 | AH10: =MAX(0,G10+M10-AB10) -> 0 | AI10: =SUM(H10:M10) -> 81.71366 | AJ10: =SUM(AC10:AH10) -> 4911.2303
A11: 7 | B11: =AC10 -> 164.85978 | C11: =AD10 -> 1715.2916 | D11: =AE10 -> 3031.0789 | E11: =AF10 -> 0 | F11: =AG10 -> 0 | G11: =AH10 -> 0 | H11: =B11*N(Debts!C7)/12 -> 2.0607473 | I11: =C11*N(Debts!C8)/12 -> 11.435278 | J11: =D11*N(Debts!C9)/12 -> 65.673375 | K11: =E11*N(Debts!C10)/12 -> 0 | L11: =F11*N(Debts!C11)/12 -> 0 | M11: =G11*N(Debts!C12)/12 -> 0 | N11: =MIN(B11+H11,N(Debts!D7)) -> 30 | O11: =MIN(C11+I11,N(Debts!D8)) -> 60 | P11: =MIN(D11+J11,N(Debts!D9)) -> 96 | Q11: =MIN(E11+K11,N(Debts!D10)) -> 0 | R11: =MIN(F11+L11,N(Debts!D11)) -> 0 | S11: =MIN(G11+M11,N(Debts!D12)) -> 0 | T11: =Debts!$B$14 -> 286 | U11: =MAX(0,T11-SUM(N11:S11)) -> 100 | V11: =_xlfn.MINIFS($B$3:$G$3,B11:G11,">0.005") -> 1 | W11: =IF(B11<=0.005,0,MIN(B11+H11,N11+IF(B$3=$V11,$U11,0))) -> 130 | X11: =IF(C11<=0.005,0,MIN(C11+I11,O11+IF(C$3=$V11,$U11,0))) -> 60 | Y11: =IF(D11<=0.005,0,MIN(D11+J11,P11+IF(D$3=$V11,$U11,0))) -> 96 | Z11: =IF(E11<=0.005,0,MIN(E11+K11,Q11+IF(E$3=$V11,$U11,0))) -> 0 | AA11: =IF(F11<=0.005,0,MIN(F11+L11,R11+IF(F$3=$V11,$U11,0))) -> 0 | AB11: =IF(G11<=0.005,0,MIN(G11+M11,S11+IF(G$3=$V11,$U11,0))) -> 0 | AC11: =MAX(0,B11+H11-W11) -> 36.920532 | AD11: =MAX(0,C11+I11-X11) -> 1666.7269 | AE11: =MAX(0,D11+J11-Y11) -> 3000.7522 | AF11: =MAX(0,E11+K11-Z11) -> 0 | AG11: =MAX(0,F11+L11-AA11) -> 0 | AH11: =MAX(0,G11+M11-AB11) -> 0 | AI11: =SUM(H11:M11) -> 79.1694 | AJ11: =SUM(AC11:AH11) -> 4704.3997
A12: 8 | B12: =AC11 -> 36.920532 | C12: =AD11 -> 1666.7269 | D12: =AE11 -> 3000.7522 | E12: =AF11 -> 0 | F12: =AG11 -> 0 | G12: =AH11 -> 0 | H12: =B12*N(Debts!C7)/12 -> 0.46150665 | I12: =C12*N(Debts!C8)/12 -> 11.111513 | J12: =D12*N(Debts!C9)/12 -> 65.016298 | K12: =E12*N(Debts!C10)/12 -> 0 | L12: =F12*N(Debts!C11)/12 -> 0 | M12: =G12*N(Debts!C12)/12 -> 0 | N12: =MIN(B12+H12,N(Debts!D7)) -> 30 | O12: =MIN(C12+I12,N(Debts!D8)) -> 60 | P12: =MIN(D12+J12,N(Debts!D9)) -> 96 | Q12: =MIN(E12+K12,N(Debts!D10)) -> 0 | R12: =MIN(F12+L12,N(Debts!D11)) -> 0 | S12: =MIN(G12+M12,N(Debts!D12)) -> 0 | T12: =Debts!$B$14 -> 286 | U12: =MAX(0,T12-SUM(N12:S12)) -> 100 | V12: =_xlfn.MINIFS($B$3:$G$3,B12:G12,">0.005") -> 1 | W12: =IF(B12<=0.005,0,MIN(B12+H12,N12+IF(B$3=$V12,$U12,0))) -> 37.382039 | X12: =IF(C12<=0.005,0,MIN(C12+I12,O12+IF(C$3=$V12,$U12,0))) -> 60 | Y12: =IF(D12<=0.005,0,MIN(D12+J12,P12+IF(D$3=$V12,$U12,0))) -> 96 | Z12: =IF(E12<=0.005,0,MIN(E12+K12,Q12+IF(E$3=$V12,$U12,0))) -> 0 | AA12: =IF(F12<=0.005,0,MIN(F12+L12,R12+IF(F$3=$V12,$U12,0))) -> 0 | AB12: =IF(G12<=0.005,0,MIN(G12+M12,S12+IF(G$3=$V12,$U12,0))) -> 0 | AC12: =MAX(0,B12+H12-W12) -> 0 | AD12: =MAX(0,C12+I12-X12) -> 1617.8384 | AE12: =MAX(0,D12+J12-Y12) -> 2969.7685 | AF12: =MAX(0,E12+K12-Z12) -> 0 | AG12: =MAX(0,F12+L12-AA12) -> 0 | AH12: =MAX(0,G12+M12-AB12) -> 0 | AI12: =SUM(H12:M12) -> 76.589318 | AJ12: =SUM(AC12:AH12) -> 4587.607
A13: 9 | B13: =AC12 -> 0 | C13: =AD12 -> 1617.8384 | D13: =AE12 -> 2969.7685 | E13: =AF12 -> 0 | F13: =AG12 -> 0 | G13: =AH12 -> 0 | H13: =B13*N(Debts!C7)/12 -> 0 | I13: =C13*N(Debts!C8)/12 -> 10.78559 | J13: =D13*N(Debts!C9)/12 -> 64.344985 | K13: =E13*N(Debts!C10)/12 -> 0 | L13: =F13*N(Debts!C11)/12 -> 0 | M13: =G13*N(Debts!C12)/12 -> 0 | N13: =MIN(B13+H13,N(Debts!D7)) -> 0 | O13: =MIN(C13+I13,N(Debts!D8)) -> 60 | P13: =MIN(D13+J13,N(Debts!D9)) -> 96 | Q13: =MIN(E13+K13,N(Debts!D10)) -> 0 | R13: =MIN(F13+L13,N(Debts!D11)) -> 0 | S13: =MIN(G13+M13,N(Debts!D12)) -> 0 | T13: =Debts!$B$14 -> 286 | U13: =MAX(0,T13-SUM(N13:S13)) -> 130 | V13: =_xlfn.MINIFS($B$3:$G$3,B13:G13,">0.005") -> 2 | W13: =IF(B13<=0.005,0,MIN(B13+H13,N13+IF(B$3=$V13,$U13,0))) -> 0 | X13: =IF(C13<=0.005,0,MIN(C13+I13,O13+IF(C$3=$V13,$U13,0))) -> 190 | Y13: =IF(D13<=0.005,0,MIN(D13+J13,P13+IF(D$3=$V13,$U13,0))) -> 96 | Z13: =IF(E13<=0.005,0,MIN(E13+K13,Q13+IF(E$3=$V13,$U13,0))) -> 0 | AA13: =IF(F13<=0.005,0,MIN(F13+L13,R13+IF(F$3=$V13,$U13,0))) -> 0 | AB13: =IF(G13<=0.005,0,MIN(G13+M13,S13+IF(G$3=$V13,$U13,0))) -> 0 | AC13: =MAX(0,B13+H13-W13) -> 0 | AD13: =MAX(0,C13+I13-X13) -> 1438.624 | AE13: =MAX(0,D13+J13-Y13) -> 2938.1135 | AF13: =MAX(0,E13+K13-Z13) -> 0 | AG13: =MAX(0,F13+L13-AA13) -> 0 | AH13: =MAX(0,G13+M13-AB13) -> 0 | AI13: =SUM(H13:M13) -> 75.130574 | AJ13: =SUM(AC13:AH13) -> 4376.7375
A14: 10 | B14: =AC13 -> 0 | C14: =AD13 -> 1438.624 | D14: =AE13 -> 2938.1135 | E14: =AF13 -> 0 | F14: =AG13 -> 0 | G14: =AH13 -> 0 | H14: =B14*N(Debts!C7)/12 -> 0 | I14: =C14*N(Debts!C8)/12 -> 9.5908268 | J14: =D14*N(Debts!C9)/12 -> 63.659126 | K14: =E14*N(Debts!C10)/12 -> 0 | L14: =F14*N(Debts!C11)/12 -> 0 | M14: =G14*N(Debts!C12)/12 -> 0 | N14: =MIN(B14+H14,N(Debts!D7)) -> 0 | O14: =MIN(C14+I14,N(Debts!D8)) -> 60 | P14: =MIN(D14+J14,N(Debts!D9)) -> 96 | Q14: =MIN(E14+K14,N(Debts!D10)) -> 0 | R14: =MIN(F14+L14,N(Debts!D11)) -> 0 | S14: =MIN(G14+M14,N(Debts!D12)) -> 0 | T14: =Debts!$B$14 -> 286 | U14: =MAX(0,T14-SUM(N14:S14)) -> 130 | V14: =_xlfn.MINIFS($B$3:$G$3,B14:G14,">0.005") -> 2 | W14: =IF(B14<=0.005,0,MIN(B14+H14,N14+IF(B$3=$V14,$U14,0))) -> 0 | X14: =IF(C14<=0.005,0,MIN(C14+I14,O14+IF(C$3=$V14,$U14,0))) -> 190 | Y14: =IF(D14<=0.005,0,MIN(D14+J14,P14+IF(D$3=$V14,$U14,0))) -> 96 | Z14: =IF(E14<=0.005,0,MIN(E14+K14,Q14+IF(E$3=$V14,$U14,0))) -> 0 | AA14: =IF(F14<=0.005,0,MIN(F14+L14,R14+IF(F$3=$V14,$U14,0))) -> 0 | AB14: =IF(G14<=0.005,0,MIN(G14+M14,S14+IF(G$3=$V14,$U14,0))) -> 0 | AC14: =MAX(0,B14+H14-W14) -> 0 | AD14: =MAX(0,C14+I14-X14) -> 1258.2149 | AE14: =MAX(0,D14+J14-Y14) -> 2905.7726 | AF14: =MAX(0,E14+K14-Z14) -> 0 | AG14: =MAX(0,F14+L14-AA14) -> 0 | AH14: =MAX(0,G14+M14-AB14) -> 0 | AI14: =SUM(H14:M14) -> 73.249953 | AJ14: =SUM(AC14:AH14) -> 4163.9875
A15: 11 | B15: =AC14 -> 0 | C15: =AD14 -> 1258.2149 | D15: =AE14 -> 2905.7726 | E15: =AF14 -> 0 | F15: =AG14 -> 0 | G15: =AH14 -> 0 | H15: =B15*N(Debts!C7)/12 -> 0 | I15: =C15*N(Debts!C8)/12 -> 8.388099 | J15: =D15*N(Debts!C9)/12 -> 62.958407 | K15: =E15*N(Debts!C10)/12 -> 0 | L15: =F15*N(Debts!C11)/12 -> 0 | M15: =G15*N(Debts!C12)/12 -> 0 | N15: =MIN(B15+H15,N(Debts!D7)) -> 0 | O15: =MIN(C15+I15,N(Debts!D8)) -> 60 | P15: =MIN(D15+J15,N(Debts!D9)) -> 96 | Q15: =MIN(E15+K15,N(Debts!D10)) -> 0 | R15: =MIN(F15+L15,N(Debts!D11)) -> 0 | S15: =MIN(G15+M15,N(Debts!D12)) -> 0 | T15: =Debts!$B$14 -> 286 | U15: =MAX(0,T15-SUM(N15:S15)) -> 130 | V15: =_xlfn.MINIFS($B$3:$G$3,B15:G15,">0.005") -> 2 | W15: =IF(B15<=0.005,0,MIN(B15+H15,N15+IF(B$3=$V15,$U15,0))) -> 0 | X15: =IF(C15<=0.005,0,MIN(C15+I15,O15+IF(C$3=$V15,$U15,0))) -> 190 | Y15: =IF(D15<=0.005,0,MIN(D15+J15,P15+IF(D$3=$V15,$U15,0))) -> 96 | Z15: =IF(E15<=0.005,0,MIN(E15+K15,Q15+IF(E$3=$V15,$U15,0))) -> 0 | AA15: =IF(F15<=0.005,0,MIN(F15+L15,R15+IF(F$3=$V15,$U15,0))) -> 0 | AB15: =IF(G15<=0.005,0,MIN(G15+M15,S15+IF(G$3=$V15,$U15,0))) -> 0 | AC15: =MAX(0,B15+H15-W15) -> 0 | AD15: =MAX(0,C15+I15-X15) -> 1076.6029 | AE15: =MAX(0,D15+J15-Y15) -> 2872.7311 | AF15: =MAX(0,E15+K15-Z15) -> 0 | AG15: =MAX(0,F15+L15-AA15) -> 0 | AH15: =MAX(0,G15+M15-AB15) -> 0 | AI15: =SUM(H15:M15) -> 71.346506 | AJ15: =SUM(AC15:AH15) -> 3949.334
A16: 12 | B16: =AC15 -> 0 | C16: =AD15 -> 1076.6029 | D16: =AE15 -> 2872.7311 | E16: =AF15 -> 0 | F16: =AG15 -> 0 | G16: =AH15 -> 0 | H16: =B16*N(Debts!C7)/12 -> 0 | I16: =C16*N(Debts!C8)/12 -> 7.177353 | J16: =D16*N(Debts!C9)/12 -> 62.242506 | K16: =E16*N(Debts!C10)/12 -> 0 | L16: =F16*N(Debts!C11)/12 -> 0 | M16: =G16*N(Debts!C12)/12 -> 0 | N16: =MIN(B16+H16,N(Debts!D7)) -> 0 | O16: =MIN(C16+I16,N(Debts!D8)) -> 60 | P16: =MIN(D16+J16,N(Debts!D9)) -> 96 | Q16: =MIN(E16+K16,N(Debts!D10)) -> 0 | R16: =MIN(F16+L16,N(Debts!D11)) -> 0 | S16: =MIN(G16+M16,N(Debts!D12)) -> 0 | T16: =Debts!$B$14 -> 286 | U16: =MAX(0,T16-SUM(N16:S16)) -> 130 | V16: =_xlfn.MINIFS($B$3:$G$3,B16:G16,">0.005") -> 2 | W16: =IF(B16<=0.005,0,MIN(B16+H16,N16+IF(B$3=$V16,$U16,0))) -> 0 | X16: =IF(C16<=0.005,0,MIN(C16+I16,O16+IF(C$3=$V16,$U16,0))) -> 190 | Y16: =IF(D16<=0.005,0,MIN(D16+J16,P16+IF(D$3=$V16,$U16,0))) -> 96 | Z16: =IF(E16<=0.005,0,MIN(E16+K16,Q16+IF(E$3=$V16,$U16,0))) -> 0 | AA16: =IF(F16<=0.005,0,MIN(F16+L16,R16+IF(F$3=$V16,$U16,0))) -> 0 | AB16: =IF(G16<=0.005,0,MIN(G16+M16,S16+IF(G$3=$V16,$U16,0))) -> 0 | AC16: =MAX(0,B16+H16-W16) -> 0 | AD16: =MAX(0,C16+I16-X16) -> 893.7803 | AE16: =MAX(0,D16+J16-Y16) -> 2838.9736 | AF16: =MAX(0,E16+K16-Z16) -> 0 | AG16: =MAX(0,F16+L16-AA16) -> 0 | AH16: =MAX(0,G16+M16-AB16) -> 0 | AI16: =SUM(H16:M16) -> 69.419859 | AJ16: =SUM(AC16:AH16) -> 3732.7539
A17: 13 | B17: =AC16 -> 0 | C17: =AD16 -> 893.7803 | D17: =AE16 -> 2838.9736 | E17: =AF16 -> 0 | F17: =AG16 -> 0 | G17: =AH16 -> 0 | H17: =B17*N(Debts!C7)/12 -> 0 | I17: =C17*N(Debts!C8)/12 -> 5.9585354 | J17: =D17*N(Debts!C9)/12 -> 61.511094 | K17: =E17*N(Debts!C10)/12 -> 0 | L17: =F17*N(Debts!C11)/12 -> 0 | M17: =G17*N(Debts!C12)/12 -> 0 | N17: =MIN(B17+H17,N(Debts!D7)) -> 0 | O17: =MIN(C17+I17,N(Debts!D8)) -> 60 | P17: =MIN(D17+J17,N(Debts!D9)) -> 96 | Q17: =MIN(E17+K17,N(Debts!D10)) -> 0 | R17: =MIN(F17+L17,N(Debts!D11)) -> 0 | S17: =MIN(G17+M17,N(Debts!D12)) -> 0 | T17: =Debts!$B$14 -> 286 | U17: =MAX(0,T17-SUM(N17:S17)) -> 130 | V17: =_xlfn.MINIFS($B$3:$G$3,B17:G17,">0.005") -> 2 | W17: =IF(B17<=0.005,0,MIN(B17+H17,N17+IF(B$3=$V17,$U17,0))) -> 0 | X17: =IF(C17<=0.005,0,MIN(C17+I17,O17+IF(C$3=$V17,$U17,0))) -> 190 | Y17: =IF(D17<=0.005,0,MIN(D17+J17,P17+IF(D$3=$V17,$U17,0))) -> 96 | Z17: =IF(E17<=0.005,0,MIN(E17+K17,Q17+IF(E$3=$V17,$U17,0))) -> 0 | AA17: =IF(F17<=0.005,0,MIN(F17+L17,R17+IF(F$3=$V17,$U17,0))) -> 0 | AB17: =IF(G17<=0.005,0,MIN(G17+M17,S17+IF(G$3=$V17,$U17,0))) -> 0 | AC17: =MAX(0,B17+H17-W17) -> 0 | AD17: =MAX(0,C17+I17-X17) -> 709.73884 | AE17: =MAX(0,D17+J17-Y17) -> 2804.4847 | AF17: =MAX(0,E17+K17-Z17) -> 0 | AG17: =MAX(0,F17+L17-AA17) -> 0 | AH17: =MAX(0,G17+M17-AB17) -> 0 | AI17: =SUM(H17:M17) -> 67.469629 | AJ17: =SUM(AC17:AH17) -> 3514.2235
A18: 14 | B18: =AC17 -> 0 | C18: =AD17 -> 709.73884 | D18: =AE17 -> 2804.4847 | E18: =AF17 -> 0 | F18: =AG17 -> 0 | G18: =AH17 -> 0 | H18: =B18*N(Debts!C7)/12 -> 0 | I18: =C18*N(Debts!C8)/12 -> 4.7315923 | J18: =D18*N(Debts!C9)/12 -> 60.763834 | K18: =E18*N(Debts!C10)/12 -> 0 | L18: =F18*N(Debts!C11)/12 -> 0 | M18: =G18*N(Debts!C12)/12 -> 0 | N18: =MIN(B18+H18,N(Debts!D7)) -> 0 | O18: =MIN(C18+I18,N(Debts!D8)) -> 60 | P18: =MIN(D18+J18,N(Debts!D9)) -> 96 | Q18: =MIN(E18+K18,N(Debts!D10)) -> 0 | R18: =MIN(F18+L18,N(Debts!D11)) -> 0 | S18: =MIN(G18+M18,N(Debts!D12)) -> 0 | T18: =Debts!$B$14 -> 286 | U18: =MAX(0,T18-SUM(N18:S18)) -> 130 | V18: =_xlfn.MINIFS($B$3:$G$3,B18:G18,">0.005") -> 2 | W18: =IF(B18<=0.005,0,MIN(B18+H18,N18+IF(B$3=$V18,$U18,0))) -> 0 | X18: =IF(C18<=0.005,0,MIN(C18+I18,O18+IF(C$3=$V18,$U18,0))) -> 190 | Y18: =IF(D18<=0.005,0,MIN(D18+J18,P18+IF(D$3=$V18,$U18,0))) -> 96 | Z18: =IF(E18<=0.005,0,MIN(E18+K18,Q18+IF(E$3=$V18,$U18,0))) -> 0 | AA18: =IF(F18<=0.005,0,MIN(F18+L18,R18+IF(F$3=$V18,$U18,0))) -> 0 | AB18: =IF(G18<=0.005,0,MIN(G18+M18,S18+IF(G$3=$V18,$U18,0))) -> 0 | AC18: =MAX(0,B18+H18-W18) -> 0 | AD18: =MAX(0,C18+I18-X18) -> 524.47043 | AE18: =MAX(0,D18+J18-Y18) -> 2769.2485 | AF18: =MAX(0,E18+K18-Z18) -> 0 | AG18: =MAX(0,F18+L18-AA18) -> 0 | AH18: =MAX(0,G18+M18-AB18) -> 0 | AI18: =SUM(H18:M18) -> 65.495426 | AJ18: =SUM(AC18:AH18) -> 3293.7189
A19: 15 | B19: =AC18 -> 0 | C19: =AD18 -> 524.47043 | D19: =AE18 -> 2769.2485 | E19: =AF18 -> 0 | F19: =AG18 -> 0 | G19: =AH18 -> 0 | H19: =B19*N(Debts!C7)/12 -> 0 | I19: =C19*N(Debts!C8)/12 -> 3.4964695 | J19: =D19*N(Debts!C9)/12 -> 60.000384 | K19: =E19*N(Debts!C10)/12 -> 0 | L19: =F19*N(Debts!C11)/12 -> 0 | M19: =G19*N(Debts!C12)/12 -> 0 | N19: =MIN(B19+H19,N(Debts!D7)) -> 0 | O19: =MIN(C19+I19,N(Debts!D8)) -> 60 | P19: =MIN(D19+J19,N(Debts!D9)) -> 96 | Q19: =MIN(E19+K19,N(Debts!D10)) -> 0 | R19: =MIN(F19+L19,N(Debts!D11)) -> 0 | S19: =MIN(G19+M19,N(Debts!D12)) -> 0 | T19: =Debts!$B$14 -> 286 | U19: =MAX(0,T19-SUM(N19:S19)) -> 130 | V19: =_xlfn.MINIFS($B$3:$G$3,B19:G19,">0.005") -> 2 | W19: =IF(B19<=0.005,0,MIN(B19+H19,N19+IF(B$3=$V19,$U19,0))) -> 0 | X19: =IF(C19<=0.005,0,MIN(C19+I19,O19+IF(C$3=$V19,$U19,0))) -> 190 | Y19: =IF(D19<=0.005,0,MIN(D19+J19,P19+IF(D$3=$V19,$U19,0))) -> 96 | Z19: =IF(E19<=0.005,0,MIN(E19+K19,Q19+IF(E$3=$V19,$U19,0))) -> 0 | AA19: =IF(F19<=0.005,0,MIN(F19+L19,R19+IF(F$3=$V19,$U19,0))) -> 0 | AB19: =IF(G19<=0.005,0,MIN(G19+M19,S19+IF(G$3=$V19,$U19,0))) -> 0 | AC19: =MAX(0,B19+H19-W19) -> 0 | AD19: =MAX(0,C19+I19-X19) -> 337.9669 | AE19: =MAX(0,D19+J19-Y19) -> 2733.2489 | AF19: =MAX(0,E19+K19-Z19) -> 0 | AG19: =MAX(0,F19+L19-AA19) -> 0 | AH19: =MAX(0,G19+M19-AB19) -> 0 | AI19: =SUM(H19:M19) -> 63.496853 | AJ19: =SUM(AC19:AH19) -> 3071.2158
A20: 16 | B20: =AC19 -> 0 | C20: =AD19 -> 337.9669 | D20: =AE19 -> 2733.2489 | E20: =AF19 -> 0 | F20: =AG19 -> 0 | G20: =AH19 -> 0 | H20: =B20*N(Debts!C7)/12 -> 0 | I20: =C20*N(Debts!C8)/12 -> 2.2531127 | J20: =D20*N(Debts!C9)/12 -> 59.220392 | K20: =E20*N(Debts!C10)/12 -> 0 | L20: =F20*N(Debts!C11)/12 -> 0 | M20: =G20*N(Debts!C12)/12 -> 0 | N20: =MIN(B20+H20,N(Debts!D7)) -> 0 | O20: =MIN(C20+I20,N(Debts!D8)) -> 60 | P20: =MIN(D20+J20,N(Debts!D9)) -> 96 | Q20: =MIN(E20+K20,N(Debts!D10)) -> 0 | R20: =MIN(F20+L20,N(Debts!D11)) -> 0 | S20: =MIN(G20+M20,N(Debts!D12)) -> 0 | T20: =Debts!$B$14 -> 286 | U20: =MAX(0,T20-SUM(N20:S20)) -> 130 | V20: =_xlfn.MINIFS($B$3:$G$3,B20:G20,">0.005") -> 2 | W20: =IF(B20<=0.005,0,MIN(B20+H20,N20+IF(B$3=$V20,$U20,0))) -> 0 | X20: =IF(C20<=0.005,0,MIN(C20+I20,O20+IF(C$3=$V20,$U20,0))) -> 190 | Y20: =IF(D20<=0.005,0,MIN(D20+J20,P20+IF(D$3=$V20,$U20,0))) -> 96 | Z20: =IF(E20<=0.005,0,MIN(E20+K20,Q20+IF(E$3=$V20,$U20,0))) -> 0 | AA20: =IF(F20<=0.005,0,MIN(F20+L20,R20+IF(F$3=$V20,$U20,0))) -> 0 | AB20: =IF(G20<=0.005,0,MIN(G20+M20,S20+IF(G$3=$V20,$U20,0))) -> 0 | AC20: =MAX(0,B20+H20-W20) -> 0 | AD20: =MAX(0,C20+I20-X20) -> 150.22001 | AE20: =MAX(0,D20+J20-Y20) -> 2696.4693 | AF20: =MAX(0,E20+K20-Z20) -> 0 | AG20: =MAX(0,F20+L20-AA20) -> 0 | AH20: =MAX(0,G20+M20-AB20) -> 0 | AI20: =SUM(H20:M20) -> 61.473505 | AJ20: =SUM(AC20:AH20) -> 2846.6893
A21: 17 | B21: =AC20 -> 0 | C21: =AD20 -> 150.22001 | D21: =AE20 -> 2696.4693 | E21: =AF20 -> 0 | F21: =AG20 -> 0 | G21: =AH20 -> 0 | H21: =B21*N(Debts!C7)/12 -> 0 | I21: =C21*N(Debts!C8)/12 -> 1.0014668 | J21: =D21*N(Debts!C9)/12 -> 58.423501 | K21: =E21*N(Debts!C10)/12 -> 0 | L21: =F21*N(Debts!C11)/12 -> 0 | M21: =G21*N(Debts!C12)/12 -> 0 | N21: =MIN(B21+H21,N(Debts!D7)) -> 0 | O21: =MIN(C21+I21,N(Debts!D8)) -> 60 | P21: =MIN(D21+J21,N(Debts!D9)) -> 96 | Q21: =MIN(E21+K21,N(Debts!D10)) -> 0 | R21: =MIN(F21+L21,N(Debts!D11)) -> 0 | S21: =MIN(G21+M21,N(Debts!D12)) -> 0 | T21: =Debts!$B$14 -> 286 | U21: =MAX(0,T21-SUM(N21:S21)) -> 130 | V21: =_xlfn.MINIFS($B$3:$G$3,B21:G21,">0.005") -> 2 | W21: =IF(B21<=0.005,0,MIN(B21+H21,N21+IF(B$3=$V21,$U21,0))) -> 0 | X21: =IF(C21<=0.005,0,MIN(C21+I21,O21+IF(C$3=$V21,$U21,0))) -> 151.22148 | Y21: =IF(D21<=0.005,0,MIN(D21+J21,P21+IF(D$3=$V21,$U21,0))) -> 96 | Z21: =IF(E21<=0.005,0,MIN(E21+K21,Q21+IF(E$3=$V21,$U21,0))) -> 0 | AA21: =IF(F21<=0.005,0,MIN(F21+L21,R21+IF(F$3=$V21,$U21,0))) -> 0 | AB21: =IF(G21<=0.005,0,MIN(G21+M21,S21+IF(G$3=$V21,$U21,0))) -> 0 | AC21: =MAX(0,B21+H21-W21) -> 0 | AD21: =MAX(0,C21+I21-X21) -> 0 | AE21: =MAX(0,D21+J21-Y21) -> 2658.8928 | AF21: =MAX(0,E21+K21-Z21) -> 0 | AG21: =MAX(0,F21+L21-AA21) -> 0 | AH21: =MAX(0,G21+M21-AB21) -> 0 | AI21: =SUM(H21:M21) -> 59.424967 | AJ21: =SUM(AC21:AH21) -> 2658.8928
A22: 18 | B22: =AC21 -> 0 | C22: =AD21 -> 0 | D22: =AE21 -> 2658.8928 | E22: =AF21 -> 0 | F22: =AG21 -> 0 | G22: =AH21 -> 0 | H22: =B22*N(Debts!C7)/12 -> 0 | I22: =C22*N(Debts!C8)/12 -> 0 | J22: =D22*N(Debts!C9)/12 -> 57.609343 | K22: =E22*N(Debts!C10)/12 -> 0 | L22: =F22*N(Debts!C11)/12 -> 0 | M22: =G22*N(Debts!C12)/12 -> 0 | N22: =MIN(B22+H22,N(Debts!D7)) -> 0 | O22: =MIN(C22+I22,N(Debts!D8)) -> 0 | P22: =MIN(D22+J22,N(Debts!D9)) -> 96 | Q22: =MIN(E22+K22,N(Debts!D10)) -> 0 | R22: =MIN(F22+L22,N(Debts!D11)) -> 0 | S22: =MIN(G22+M22,N(Debts!D12)) -> 0 | T22: =Debts!$B$14 -> 286 | U22: =MAX(0,T22-SUM(N22:S22)) -> 190 | V22: =_xlfn.MINIFS($B$3:$G$3,B22:G22,">0.005") -> 3 | W22: =IF(B22<=0.005,0,MIN(B22+H22,N22+IF(B$3=$V22,$U22,0))) -> 0 | X22: =IF(C22<=0.005,0,MIN(C22+I22,O22+IF(C$3=$V22,$U22,0))) -> 0 | Y22: =IF(D22<=0.005,0,MIN(D22+J22,P22+IF(D$3=$V22,$U22,0))) -> 286 | Z22: =IF(E22<=0.005,0,MIN(E22+K22,Q22+IF(E$3=$V22,$U22,0))) -> 0 | AA22: =IF(F22<=0.005,0,MIN(F22+L22,R22+IF(F$3=$V22,$U22,0))) -> 0 | AB22: =IF(G22<=0.005,0,MIN(G22+M22,S22+IF(G$3=$V22,$U22,0))) -> 0 | AC22: =MAX(0,B22+H22-W22) -> 0 | AD22: =MAX(0,C22+I22-X22) -> 0 | AE22: =MAX(0,D22+J22-Y22) -> 2430.5021 | AF22: =MAX(0,E22+K22-Z22) -> 0 | AG22: =MAX(0,F22+L22-AA22) -> 0 | AH22: =MAX(0,G22+M22-AB22) -> 0 | AI22: =SUM(H22:M22) -> 57.609343 | AJ22: =SUM(AC22:AH22) -> 2430.5021
A23: 19 | B23: =AC22 -> 0 | C23: =AD22 -> 0 | D23: =AE22 -> 2430.5021 | E23: =AF22 -> 0 | F23: =AG22 -> 0 | G23: =AH22 -> 0 | H23: =B23*N(Debts!C7)/12 -> 0 | I23: =C23*N(Debts!C8)/12 -> 0 | J23: =D23*N(Debts!C9)/12 -> 52.660879 | K23: =E23*N(Debts!C10)/12 -> 0 | L23: =F23*N(Debts!C11)/12 -> 0 | M23: =G23*N(Debts!C12)/12 -> 0 | N23: =MIN(B23+H23,N(Debts!D7)) -> 0 | O23: =MIN(C23+I23,N(Debts!D8)) -> 0 | P23: =MIN(D23+J23,N(Debts!D9)) -> 96 | Q23: =MIN(E23+K23,N(Debts!D10)) -> 0 | R23: =MIN(F23+L23,N(Debts!D11)) -> 0 | S23: =MIN(G23+M23,N(Debts!D12)) -> 0 | T23: =Debts!$B$14 -> 286 | U23: =MAX(0,T23-SUM(N23:S23)) -> 190 | V23: =_xlfn.MINIFS($B$3:$G$3,B23:G23,">0.005") -> 3 | W23: =IF(B23<=0.005,0,MIN(B23+H23,N23+IF(B$3=$V23,$U23,0))) -> 0 | X23: =IF(C23<=0.005,0,MIN(C23+I23,O23+IF(C$3=$V23,$U23,0))) -> 0 | Y23: =IF(D23<=0.005,0,MIN(D23+J23,P23+IF(D$3=$V23,$U23,0))) -> 286 | Z23: =IF(E23<=0.005,0,MIN(E23+K23,Q23+IF(E$3=$V23,$U23,0))) -> 0 | AA23: =IF(F23<=0.005,0,MIN(F23+L23,R23+IF(F$3=$V23,$U23,0))) -> 0 | AB23: =IF(G23<=0.005,0,MIN(G23+M23,S23+IF(G$3=$V23,$U23,0))) -> 0 | AC23: =MAX(0,B23+H23-W23) -> 0 | AD23: =MAX(0,C23+I23-X23) -> 0 | AE23: =MAX(0,D23+J23-Y23) -> 2197.163 | AF23: =MAX(0,E23+K23-Z23) -> 0 | AG23: =MAX(0,F23+L23-AA23) -> 0 | AH23: =MAX(0,G23+M23-AB23) -> 0 | AI23: =SUM(H23:M23) -> 52.660879 | AJ23: =SUM(AC23:AH23) -> 2197.163
A24: 20 | B24: =AC23 -> 0 | C24: =AD23 -> 0 | D24: =AE23 -> 2197.163 | E24: =AF23 -> 0 | F24: =AG23 -> 0 | G24: =AH23 -> 0 | H24: =B24*N(Debts!C7)/12 -> 0 | I24: =C24*N(Debts!C8)/12 -> 0 | J24: =D24*N(Debts!C9)/12 -> 47.605198 | K24: =E24*N(Debts!C10)/12 -> 0 | L24: =F24*N(Debts!C11)/12 -> 0 | M24: =G24*N(Debts!C12)/12 -> 0 | N24: =MIN(B24+H24,N(Debts!D7)) -> 0 | O24: =MIN(C24+I24,N(Debts!D8)) -> 0 | P24: =MIN(D24+J24,N(Debts!D9)) -> 96 | Q24: =MIN(E24+K24,N(Debts!D10)) -> 0 | R24: =MIN(F24+L24,N(Debts!D11)) -> 0 | S24: =MIN(G24+M24,N(Debts!D12)) -> 0 | T24: =Debts!$B$14 -> 286 | U24: =MAX(0,T24-SUM(N24:S24)) -> 190 | V24: =_xlfn.MINIFS($B$3:$G$3,B24:G24,">0.005") -> 3 | W24: =IF(B24<=0.005,0,MIN(B24+H24,N24+IF(B$3=$V24,$U24,0))) -> 0 | X24: =IF(C24<=0.005,0,MIN(C24+I24,O24+IF(C$3=$V24,$U24,0))) -> 0 | Y24: =IF(D24<=0.005,0,MIN(D24+J24,P24+IF(D$3=$V24,$U24,0))) -> 286 | Z24: =IF(E24<=0.005,0,MIN(E24+K24,Q24+IF(E$3=$V24,$U24,0))) -> 0 | AA24: =IF(F24<=0.005,0,MIN(F24+L24,R24+IF(F$3=$V24,$U24,0))) -> 0 | AB24: =IF(G24<=0.005,0,MIN(G24+M24,S24+IF(G$3=$V24,$U24,0))) -> 0 | AC24: =MAX(0,B24+H24-W24) -> 0 | AD24: =MAX(0,C24+I24-X24) -> 0 | AE24: =MAX(0,D24+J24-Y24) -> 1958.7682 | AF24: =MAX(0,E24+K24-Z24) -> 0 | AG24: =MAX(0,F24+L24-AA24) -> 0 | AH24: =MAX(0,G24+M24-AB24) -> 0 | AI24: =SUM(H24:M24) -> 47.605198 | AJ24: =SUM(AC24:AH24) -> 1958.7682
A25: 21 | B25: =AC24 -> 0 | C25: =AD24 -> 0 | D25: =AE24 -> 1958.7682 | E25: =AF24 -> 0 | F25: =AG24 -> 0 | G25: =AH24 -> 0 | H25: =B25*N(Debts!C7)/12 -> 0 | I25: =C25*N(Debts!C8)/12 -> 0 | J25: =D25*N(Debts!C9)/12 -> 42.439977 | K25: =E25*N(Debts!C10)/12 -> 0 | L25: =F25*N(Debts!C11)/12 -> 0 | M25: =G25*N(Debts!C12)/12 -> 0 | N25: =MIN(B25+H25,N(Debts!D7)) -> 0 | O25: =MIN(C25+I25,N(Debts!D8)) -> 0 | P25: =MIN(D25+J25,N(Debts!D9)) -> 96 | Q25: =MIN(E25+K25,N(Debts!D10)) -> 0 | R25: =MIN(F25+L25,N(Debts!D11)) -> 0 | S25: =MIN(G25+M25,N(Debts!D12)) -> 0 | T25: =Debts!$B$14 -> 286 | U25: =MAX(0,T25-SUM(N25:S25)) -> 190 | V25: =_xlfn.MINIFS($B$3:$G$3,B25:G25,">0.005") -> 3 | W25: =IF(B25<=0.005,0,MIN(B25+H25,N25+IF(B$3=$V25,$U25,0))) -> 0 | X25: =IF(C25<=0.005,0,MIN(C25+I25,O25+IF(C$3=$V25,$U25,0))) -> 0 | Y25: =IF(D25<=0.005,0,MIN(D25+J25,P25+IF(D$3=$V25,$U25,0))) -> 286 | Z25: =IF(E25<=0.005,0,MIN(E25+K25,Q25+IF(E$3=$V25,$U25,0))) -> 0 | AA25: =IF(F25<=0.005,0,MIN(F25+L25,R25+IF(F$3=$V25,$U25,0))) -> 0 | AB25: =IF(G25<=0.005,0,MIN(G25+M25,S25+IF(G$3=$V25,$U25,0))) -> 0 | AC25: =MAX(0,B25+H25-W25) -> 0 | AD25: =MAX(0,C25+I25-X25) -> 0 | AE25: =MAX(0,D25+J25-Y25) -> 1715.2082 | AF25: =MAX(0,E25+K25-Z25) -> 0 | AG25: =MAX(0,F25+L25-AA25) -> 0 | AH25: =MAX(0,G25+M25-AB25) -> 0 | AI25: =SUM(H25:M25) -> 42.439977 | AJ25: =SUM(AC25:AH25) -> 1715.2082
A26: 22 | B26: =AC25 -> 0 | C26: =AD25 -> 0 | D26: =AE25 -> 1715.2082 | E26: =AF25 -> 0 | F26: =AG25 -> 0 | G26: =AH25 -> 0 | H26: =B26*N(Debts!C7)/12 -> 0 | I26: =C26*N(Debts!C8)/12 -> 0 | J26: =D26*N(Debts!C9)/12 -> 37.162843 | K26: =E26*N(Debts!C10)/12 -> 0 | L26: =F26*N(Debts!C11)/12 -> 0 | M26: =G26*N(Debts!C12)/12 -> 0 | N26: =MIN(B26+H26,N(Debts!D7)) -> 0 | O26: =MIN(C26+I26,N(Debts!D8)) -> 0 | P26: =MIN(D26+J26,N(Debts!D9)) -> 96 | Q26: =MIN(E26+K26,N(Debts!D10)) -> 0 | R26: =MIN(F26+L26,N(Debts!D11)) -> 0 | S26: =MIN(G26+M26,N(Debts!D12)) -> 0 | T26: =Debts!$B$14 -> 286 | U26: =MAX(0,T26-SUM(N26:S26)) -> 190 | V26: =_xlfn.MINIFS($B$3:$G$3,B26:G26,">0.005") -> 3 | W26: =IF(B26<=0.005,0,MIN(B26+H26,N26+IF(B$3=$V26,$U26,0))) -> 0 | X26: =IF(C26<=0.005,0,MIN(C26+I26,O26+IF(C$3=$V26,$U26,0))) -> 0 | Y26: =IF(D26<=0.005,0,MIN(D26+J26,P26+IF(D$3=$V26,$U26,0))) -> 286 | Z26: =IF(E26<=0.005,0,MIN(E26+K26,Q26+IF(E$3=$V26,$U26,0))) -> 0 | AA26: =IF(F26<=0.005,0,MIN(F26+L26,R26+IF(F$3=$V26,$U26,0))) -> 0 | AB26: =IF(G26<=0.005,0,MIN(G26+M26,S26+IF(G$3=$V26,$U26,0))) -> 0 | AC26: =MAX(0,B26+H26-W26) -> 0 | AD26: =MAX(0,C26+I26-X26) -> 0 | AE26: =MAX(0,D26+J26-Y26) -> 1466.371 | AF26: =MAX(0,E26+K26-Z26) -> 0 | AG26: =MAX(0,F26+L26-AA26) -> 0 | AH26: =MAX(0,G26+M26-AB26) -> 0 | AI26: =SUM(H26:M26) -> 37.162843 | AJ26: =SUM(AC26:AH26) -> 1466.371
A27: 23 | B27: =AC26 -> 0 | C27: =AD26 -> 0 | D27: =AE26 -> 1466.371 | E27: =AF26 -> 0 | F27: =AG26 -> 0 | G27: =AH26 -> 0 | H27: =B27*N(Debts!C7)/12 -> 0 | I27: =C27*N(Debts!C8)/12 -> 0 | J27: =D27*N(Debts!C9)/12 -> 31.771372 | K27: =E27*N(Debts!C10)/12 -> 0 | L27: =F27*N(Debts!C11)/12 -> 0 | M27: =G27*N(Debts!C12)/12 -> 0 | N27: =MIN(B27+H27,N(Debts!D7)) -> 0 | O27: =MIN(C27+I27,N(Debts!D8)) -> 0 | P27: =MIN(D27+J27,N(Debts!D9)) -> 96 | Q27: =MIN(E27+K27,N(Debts!D10)) -> 0 | R27: =MIN(F27+L27,N(Debts!D11)) -> 0 | S27: =MIN(G27+M27,N(Debts!D12)) -> 0 | T27: =Debts!$B$14 -> 286 | U27: =MAX(0,T27-SUM(N27:S27)) -> 190 | V27: =_xlfn.MINIFS($B$3:$G$3,B27:G27,">0.005") -> 3 | W27: =IF(B27<=0.005,0,MIN(B27+H27,N27+IF(B$3=$V27,$U27,0))) -> 0 | X27: =IF(C27<=0.005,0,MIN(C27+I27,O27+IF(C$3=$V27,$U27,0))) -> 0 | Y27: =IF(D27<=0.005,0,MIN(D27+J27,P27+IF(D$3=$V27,$U27,0))) -> 286 | Z27: =IF(E27<=0.005,0,MIN(E27+K27,Q27+IF(E$3=$V27,$U27,0))) -> 0 | AA27: =IF(F27<=0.005,0,MIN(F27+L27,R27+IF(F$3=$V27,$U27,0))) -> 0 | AB27: =IF(G27<=0.005,0,MIN(G27+M27,S27+IF(G$3=$V27,$U27,0))) -> 0 | AC27: =MAX(0,B27+H27-W27) -> 0 | AD27: =MAX(0,C27+I27-X27) -> 0 | AE27: =MAX(0,D27+J27-Y27) -> 1212.1424 | AF27: =MAX(0,E27+K27-Z27) -> 0 | AG27: =MAX(0,F27+L27-AA27) -> 0 | AH27: =MAX(0,G27+M27-AB27) -> 0 | AI27: =SUM(H27:M27) -> 31.771372 | AJ27: =SUM(AC27:AH27) -> 1212.1424
A28: 24 | B28: =AC27 -> 0 | C28: =AD27 -> 0 | D28: =AE27 -> 1212.1424 | E28: =AF27 -> 0 | F28: =AG27 -> 0 | G28: =AH27 -> 0 | H28: =B28*N(Debts!C7)/12 -> 0 | I28: =C28*N(Debts!C8)/12 -> 0 | J28: =D28*N(Debts!C9)/12 -> 26.263085 | K28: =E28*N(Debts!C10)/12 -> 0 | L28: =F28*N(Debts!C11)/12 -> 0 | M28: =G28*N(Debts!C12)/12 -> 0 | N28: =MIN(B28+H28,N(Debts!D7)) -> 0 | O28: =MIN(C28+I28,N(Debts!D8)) -> 0 | P28: =MIN(D28+J28,N(Debts!D9)) -> 96 | Q28: =MIN(E28+K28,N(Debts!D10)) -> 0 | R28: =MIN(F28+L28,N(Debts!D11)) -> 0 | S28: =MIN(G28+M28,N(Debts!D12)) -> 0 | T28: =Debts!$B$14 -> 286 | U28: =MAX(0,T28-SUM(N28:S28)) -> 190 | V28: =_xlfn.MINIFS($B$3:$G$3,B28:G28,">0.005") -> 3 | W28: =IF(B28<=0.005,0,MIN(B28+H28,N28+IF(B$3=$V28,$U28,0))) -> 0 | X28: =IF(C28<=0.005,0,MIN(C28+I28,O28+IF(C$3=$V28,$U28,0))) -> 0 | Y28: =IF(D28<=0.005,0,MIN(D28+J28,P28+IF(D$3=$V28,$U28,0))) -> 286 | Z28: =IF(E28<=0.005,0,MIN(E28+K28,Q28+IF(E$3=$V28,$U28,0))) -> 0 | AA28: =IF(F28<=0.005,0,MIN(F28+L28,R28+IF(F$3=$V28,$U28,0))) -> 0 | AB28: =IF(G28<=0.005,0,MIN(G28+M28,S28+IF(G$3=$V28,$U28,0))) -> 0 | AC28: =MAX(0,B28+H28-W28) -> 0 | AD28: =MAX(0,C28+I28-X28) -> 0 | AE28: =MAX(0,D28+J28-Y28) -> 952.40546 | AF28: =MAX(0,E28+K28-Z28) -> 0 | AG28: =MAX(0,F28+L28-AA28) -> 0 | AH28: =MAX(0,G28+M28-AB28) -> 0 | AI28: =SUM(H28:M28) -> 26.263085 | AJ28: =SUM(AC28:AH28) -> 952.40546
A29: 25 | B29: =AC28 -> 0 | C29: =AD28 -> 0 | D29: =AE28 -> 952.40546 | E29: =AF28 -> 0 | F29: =AG28 -> 0 | G29: =AH28 -> 0 | H29: =B29*N(Debts!C7)/12 -> 0 | I29: =C29*N(Debts!C8)/12 -> 0 | J29: =D29*N(Debts!C9)/12 -> 20.635452 | K29: =E29*N(Debts!C10)/12 -> 0 | L29: =F29*N(Debts!C11)/12 -> 0 | M29: =G29*N(Debts!C12)/12 -> 0 | N29: =MIN(B29+H29,N(Debts!D7)) -> 0 | O29: =MIN(C29+I29,N(Debts!D8)) -> 0 | P29: =MIN(D29+J29,N(Debts!D9)) -> 96 | Q29: =MIN(E29+K29,N(Debts!D10)) -> 0 | R29: =MIN(F29+L29,N(Debts!D11)) -> 0 | S29: =MIN(G29+M29,N(Debts!D12)) -> 0 | T29: =Debts!$B$14 -> 286 | U29: =MAX(0,T29-SUM(N29:S29)) -> 190 | V29: =_xlfn.MINIFS($B$3:$G$3,B29:G29,">0.005") -> 3 | W29: =IF(B29<=0.005,0,MIN(B29+H29,N29+IF(B$3=$V29,$U29,0))) -> 0 | X29: =IF(C29<=0.005,0,MIN(C29+I29,O29+IF(C$3=$V29,$U29,0))) -> 0 | Y29: =IF(D29<=0.005,0,MIN(D29+J29,P29+IF(D$3=$V29,$U29,0))) -> 286 | Z29: =IF(E29<=0.005,0,MIN(E29+K29,Q29+IF(E$3=$V29,$U29,0))) -> 0 | AA29: =IF(F29<=0.005,0,MIN(F29+L29,R29+IF(F$3=$V29,$U29,0))) -> 0 | AB29: =IF(G29<=0.005,0,MIN(G29+M29,S29+IF(G$3=$V29,$U29,0))) -> 0 | AC29: =MAX(0,B29+H29-W29) -> 0 | AD29: =MAX(0,C29+I29-X29) -> 0 | AE29: =MAX(0,D29+J29-Y29) -> 687.04091 | AF29: =MAX(0,E29+K29-Z29) -> 0 | AG29: =MAX(0,F29+L29-AA29) -> 0 | AH29: =MAX(0,G29+M29-AB29) -> 0 | AI29: =SUM(H29:M29) -> 20.635452 | AJ29: =SUM(AC29:AH29) -> 687.04091
A30: 26 | B30: =AC29 -> 0 | C30: =AD29 -> 0 | D30: =AE29 -> 687.04091 | E30: =AF29 -> 0 | F30: =AG29 -> 0 | G30: =AH29 -> 0 | H30: =B30*N(Debts!C7)/12 -> 0 | I30: =C30*N(Debts!C8)/12 -> 0 | J30: =D30*N(Debts!C9)/12 -> 14.885886 | K30: =E30*N(Debts!C10)/12 -> 0 | L30: =F30*N(Debts!C11)/12 -> 0 | M30: =G30*N(Debts!C12)/12 -> 0 | N30: =MIN(B30+H30,N(Debts!D7)) -> 0 | O30: =MIN(C30+I30,N(Debts!D8)) -> 0 | P30: =MIN(D30+J30,N(Debts!D9)) -> 96 | Q30: =MIN(E30+K30,N(Debts!D10)) -> 0 | R30: =MIN(F30+L30,N(Debts!D11)) -> 0 | S30: =MIN(G30+M30,N(Debts!D12)) -> 0 | T30: =Debts!$B$14 -> 286 | U30: =MAX(0,T30-SUM(N30:S30)) -> 190 | V30: =_xlfn.MINIFS($B$3:$G$3,B30:G30,">0.005") -> 3 | W30: =IF(B30<=0.005,0,MIN(B30+H30,N30+IF(B$3=$V30,$U30,0))) -> 0 | X30: =IF(C30<=0.005,0,MIN(C30+I30,O30+IF(C$3=$V30,$U30,0))) -> 0 | Y30: =IF(D30<=0.005,0,MIN(D30+J30,P30+IF(D$3=$V30,$U30,0))) -> 286 | Z30: =IF(E30<=0.005,0,MIN(E30+K30,Q30+IF(E$3=$V30,$U30,0))) -> 0 | AA30: =IF(F30<=0.005,0,MIN(F30+L30,R30+IF(F$3=$V30,$U30,0))) -> 0 | AB30: =IF(G30<=0.005,0,MIN(G30+M30,S30+IF(G$3=$V30,$U30,0))) -> 0 | AC30: =MAX(0,B30+H30-W30) -> 0 | AD30: =MAX(0,C30+I30-X30) -> 0 | AE30: =MAX(0,D30+J30-Y30) -> 415.9268 | AF30: =MAX(0,E30+K30-Z30) -> 0 | AG30: =MAX(0,F30+L30-AA30) -> 0 | AH30: =MAX(0,G30+M30-AB30) -> 0 | AI30: =SUM(H30:M30) -> 14.885886 | AJ30: =SUM(AC30:AH30) -> 415.9268
A31: 27 | B31: =AC30 -> 0 | C31: =AD30 -> 0 | D31: =AE30 -> 415.9268 | E31: =AF30 -> 0 | F31: =AG30 -> 0 | G31: =AH30 -> 0 | H31: =B31*N(Debts!C7)/12 -> 0 | I31: =C31*N(Debts!C8)/12 -> 0 | J31: =D31*N(Debts!C9)/12 -> 9.0117473 | K31: =E31*N(Debts!C10)/12 -> 0 | L31: =F31*N(Debts!C11)/12 -> 0 | M31: =G31*N(Debts!C12)/12 -> 0 | N31: =MIN(B31+H31,N(Debts!D7)) -> 0 | O31: =MIN(C31+I31,N(Debts!D8)) -> 0 | P31: =MIN(D31+J31,N(Debts!D9)) -> 96 | Q31: =MIN(E31+K31,N(Debts!D10)) -> 0 | R31: =MIN(F31+L31,N(Debts!D11)) -> 0 | S31: =MIN(G31+M31,N(Debts!D12)) -> 0 | T31: =Debts!$B$14 -> 286 | U31: =MAX(0,T31-SUM(N31:S31)) -> 190 | V31: =_xlfn.MINIFS($B$3:$G$3,B31:G31,">0.005") -> 3 | W31: =IF(B31<=0.005,0,MIN(B31+H31,N31+IF(B$3=$V31,$U31,0))) -> 0 | X31: =IF(C31<=0.005,0,MIN(C31+I31,O31+IF(C$3=$V31,$U31,0))) -> 0 | Y31: =IF(D31<=0.005,0,MIN(D31+J31,P31+IF(D$3=$V31,$U31,0))) -> 286 | Z31: =IF(E31<=0.005,0,MIN(E31+K31,Q31+IF(E$3=$V31,$U31,0))) -> 0 | AA31: =IF(F31<=0.005,0,MIN(F31+L31,R31+IF(F$3=$V31,$U31,0))) -> 0 | AB31: =IF(G31<=0.005,0,MIN(G31+M31,S31+IF(G$3=$V31,$U31,0))) -> 0 | AC31: =MAX(0,B31+H31-W31) -> 0 | AD31: =MAX(0,C31+I31-X31) -> 0 | AE31: =MAX(0,D31+J31-Y31) -> 138.93854 | AF31: =MAX(0,E31+K31-Z31) -> 0 | AG31: =MAX(0,F31+L31-AA31) -> 0 | AH31: =MAX(0,G31+M31-AB31) -> 0 | AI31: =SUM(H31:M31) -> 9.0117473 | AJ31: =SUM(AC31:AH31) -> 138.93854
A32: 28 | B32: =AC31 -> 0 | C32: =AD31 -> 0 | D32: =AE31 -> 138.93854 | E32: =AF31 -> 0 | F32: =AG31 -> 0 | G32: =AH31 -> 0 | H32: =B32*N(Debts!C7)/12 -> 0 | I32: =C32*N(Debts!C8)/12 -> 0 | J32: =D32*N(Debts!C9)/12 -> 3.0103351 | K32: =E32*N(Debts!C10)/12 -> 0 | L32: =F32*N(Debts!C11)/12 -> 0 | M32: =G32*N(Debts!C12)/12 -> 0 | N32: =MIN(B32+H32,N(Debts!D7)) -> 0 | O32: =MIN(C32+I32,N(Debts!D8)) -> 0 | P32: =MIN(D32+J32,N(Debts!D9)) -> 96 | Q32: =MIN(E32+K32,N(Debts!D10)) -> 0 | R32: =MIN(F32+L32,N(Debts!D11)) -> 0 | S32: =MIN(G32+M32,N(Debts!D12)) -> 0 | T32: =Debts!$B$14 -> 286 | U32: =MAX(0,T32-SUM(N32:S32)) -> 190 | V32: =_xlfn.MINIFS($B$3:$G$3,B32:G32,">0.005") -> 3 | W32: =IF(B32<=0.005,0,MIN(B32+H32,N32+IF(B$3=$V32,$U32,0))) -> 0 | X32: =IF(C32<=0.005,0,MIN(C32+I32,O32+IF(C$3=$V32,$U32,0))) -> 0 | Y32: =IF(D32<=0.005,0,MIN(D32+J32,P32+IF(D$3=$V32,$U32,0))) -> 141.94888 | Z32: =IF(E32<=0.005,0,MIN(E32+K32,Q32+IF(E$3=$V32,$U32,0))) -> 0 | AA32: =IF(F32<=0.005,0,MIN(F32+L32,R32+IF(F$3=$V32,$U32,0))) -> 0 | AB32: =IF(G32<=0.005,0,MIN(G32+M32,S32+IF(G$3=$V32,$U32,0))) -> 0 | AC32: =MAX(0,B32+H32-W32) -> 0 | AD32: =MAX(0,C32+I32-X32) -> 0 | AE32: =MAX(0,D32+J32-Y32) -> 0 | AF32: =MAX(0,E32+K32-Z32) -> 0 | AG32: =MAX(0,F32+L32-AA32) -> 0 | AH32: =MAX(0,G32+M32-AB32) -> 0 | AI32: =SUM(H32:M32) -> 3.0103351 | AJ32: =SUM(AC32:AH32) -> 0
A33: 29 | B33: =AC32 -> 0 | C33: =AD32 -> 0 | D33: =AE32 -> 0 | E33: =AF32 -> 0 | F33: =AG32 -> 0 | G33: =AH32 -> 0 | H33: =B33*N(Debts!C7)/12 -> 0 | I33: =C33*N(Debts!C8)/12 -> 0 | J33: =D33*N(Debts!C9)/12 -> 0 | K33: =E33*N(Debts!C10)/12 -> 0 | L33: =F33*N(Debts!C11)/12 -> 0 | M33: =G33*N(Debts!C12)/12 -> 0 | N33: =MIN(B33+H33,N(Debts!D7)) -> 0 | O33: =MIN(C33+I33,N(Debts!D8)) -> 0 | P33: =MIN(D33+J33,N(Debts!D9)) -> 0 | Q33: =MIN(E33+K33,N(Debts!D10)) -> 0 | R33: =MIN(F33+L33,N(Debts!D11)) -> 0 | S33: =MIN(G33+M33,N(Debts!D12)) -> 0 | T33: =Debts!$B$14 -> 286 | U33: =MAX(0,T33-SUM(N33:S33)) -> 286 | V33: =_xlfn.MINIFS($B$3:$G$3,B33:G33,">0.005") -> 0 | W33: =IF(B33<=0.005,0,MIN(B33+H33,N33+IF(B$3=$V33,$U33,0))) -> 0 | X33: =IF(C33<=0.005,0,MIN(C33+I33,O33+IF(C$3=$V33,$U33,0))) -> 0 | Y33: =IF(D33<=0.005,0,MIN(D33+J33,P33+IF(D$3=$V33,$U33,0))) -> 0 | Z33: =IF(E33<=0.005,0,MIN(E33+K33,Q33+IF(E$3=$V33,$U33,0))) -> 0 | AA33: =IF(F33<=0.005,0,MIN(F33+L33,R33+IF(F$3=$V33,$U33,0))) -> 0 | AB33: =IF(G33<=0.005,0,MIN(G33+M33,S33+IF(G$3=$V33,$U33,0))) -> 0 | AC33: =MAX(0,B33+H33-W33) -> 0 | AD33: =MAX(0,C33+I33-X33) -> 0 | AE33: =MAX(0,D33+J33-Y33) -> 0 | AF33: =MAX(0,E33+K33-Z33) -> 0 | AG33: =MAX(0,F33+L33-AA33) -> 0 | AH33: =MAX(0,G33+M33-AB33) -> 0 | AI33: =SUM(H33:M33) -> 0 | AJ33: =SUM(AC33:AH33) -> 0
A34: 30 | B34: =AC33 -> 0 | C34: =AD33 -> 0 | D34: =AE33 -> 0 | E34: =AF33 -> 0 | F34: =AG33 -> 0 | G34: =AH33 -> 0 | H34: =B34*N(Debts!C7)/12 -> 0 | I34: =C34*N(Debts!C8)/12 -> 0 | J34: =D34*N(Debts!C9)/12 -> 0 | K34: =E34*N(Debts!C10)/12 -> 0 | L34: =F34*N(Debts!C11)/12 -> 0 | M34: =G34*N(Debts!C12)/12 -> 0 | N34: =MIN(B34+H34,N(Debts!D7)) -> 0 | O34: =MIN(C34+I34,N(Debts!D8)) -> 0 | P34: =MIN(D34+J34,N(Debts!D9)) -> 0 | Q34: =MIN(E34+K34,N(Debts!D10)) -> 0 | R34: =MIN(F34+L34,N(Debts!D11)) -> 0 | S34: =MIN(G34+M34,N(Debts!D12)) -> 0 | T34: =Debts!$B$14 -> 286 | U34: =MAX(0,T34-SUM(N34:S34)) -> 286 | V34: =_xlfn.MINIFS($B$3:$G$3,B34:G34,">0.005") -> 0 | W34: =IF(B34<=0.005,0,MIN(B34+H34,N34+IF(B$3=$V34,$U34,0))) -> 0 | X34: =IF(C34<=0.005,0,MIN(C34+I34,O34+IF(C$3=$V34,$U34,0))) -> 0 | Y34: =IF(D34<=0.005,0,MIN(D34+J34,P34+IF(D$3=$V34,$U34,0))) -> 0 | Z34: =IF(E34<=0.005,0,MIN(E34+K34,Q34+IF(E$3=$V34,$U34,0))) -> 0 | AA34: =IF(F34<=0.005,0,MIN(F34+L34,R34+IF(F$3=$V34,$U34,0))) -> 0 | AB34: =IF(G34<=0.005,0,MIN(G34+M34,S34+IF(G$3=$V34,$U34,0))) -> 0 | AC34: =MAX(0,B34+H34-W34) -> 0 | AD34: =MAX(0,C34+I34-X34) -> 0 | AE34: =MAX(0,D34+J34-Y34) -> 0 | AF34: =MAX(0,E34+K34-Z34) -> 0 | AG34: =MAX(0,F34+L34-AA34) -> 0 | AH34: =MAX(0,G34+M34-AB34) -> 0 | AI34: =SUM(H34:M34) -> 0 | AJ34: =SUM(AC34:AH34) -> 0
A35: 31 | B35: =AC34 -> 0 | C35: =AD34 -> 0 | D35: =AE34 -> 0 | E35: =AF34 -> 0 | F35: =AG34 -> 0 | G35: =AH34 -> 0 | H35: =B35*N(Debts!C7)/12 -> 0 | I35: =C35*N(Debts!C8)/12 -> 0 | J35: =D35*N(Debts!C9)/12 -> 0 | K35: =E35*N(Debts!C10)/12 -> 0 | L35: =F35*N(Debts!C11)/12 -> 0 | M35: =G35*N(Debts!C12)/12 -> 0 | N35: =MIN(B35+H35,N(Debts!D7)) -> 0 | O35: =MIN(C35+I35,N(Debts!D8)) -> 0 | P35: =MIN(D35+J35,N(Debts!D9)) -> 0 | Q35: =MIN(E35+K35,N(Debts!D10)) -> 0 | R35: =MIN(F35+L35,N(Debts!D11)) -> 0 | S35: =MIN(G35+M35,N(Debts!D12)) -> 0 | T35: =Debts!$B$14 -> 286 | U35: =MAX(0,T35-SUM(N35:S35)) -> 286 | V35: =_xlfn.MINIFS($B$3:$G$3,B35:G35,">0.005") -> 0 | W35: =IF(B35<=0.005,0,MIN(B35+H35,N35+IF(B$3=$V35,$U35,0))) -> 0 | X35: =IF(C35<=0.005,0,MIN(C35+I35,O35+IF(C$3=$V35,$U35,0))) -> 0 | Y35: =IF(D35<=0.005,0,MIN(D35+J35,P35+IF(D$3=$V35,$U35,0))) -> 0 | Z35: =IF(E35<=0.005,0,MIN(E35+K35,Q35+IF(E$3=$V35,$U35,0))) -> 0 | AA35: =IF(F35<=0.005,0,MIN(F35+L35,R35+IF(F$3=$V35,$U35,0))) -> 0 | AB35: =IF(G35<=0.005,0,MIN(G35+M35,S35+IF(G$3=$V35,$U35,0))) -> 0 | AC35: =MAX(0,B35+H35-W35) -> 0 | AD35: =MAX(0,C35+I35-X35) -> 0 | AE35: =MAX(0,D35+J35-Y35) -> 0 | AF35: =MAX(0,E35+K35-Z35) -> 0 | AG35: =MAX(0,F35+L35-AA35) -> 0 | AH35: =MAX(0,G35+M35-AB35) -> 0 | AI35: =SUM(H35:M35) -> 0 | AJ35: =SUM(AC35:AH35) -> 0
A36: 32 | B36: =AC35 -> 0 | C36: =AD35 -> 0 | D36: =AE35 -> 0 | E36: =AF35 -> 0 | F36: =AG35 -> 0 | G36: =AH35 -> 0 | H36: =B36*N(Debts!C7)/12 -> 0 | I36: =C36*N(Debts!C8)/12 -> 0 | J36: =D36*N(Debts!C9)/12 -> 0 | K36: =E36*N(Debts!C10)/12 -> 0 | L36: =F36*N(Debts!C11)/12 -> 0 | M36: =G36*N(Debts!C12)/12 -> 0 | N36: =MIN(B36+H36,N(Debts!D7)) -> 0 | O36: =MIN(C36+I36,N(Debts!D8)) -> 0 | P36: =MIN(D36+J36,N(Debts!D9)) -> 0 | Q36: =MIN(E36+K36,N(Debts!D10)) -> 0 | R36: =MIN(F36+L36,N(Debts!D11)) -> 0 | S36: =MIN(G36+M36,N(Debts!D12)) -> 0 | T36: =Debts!$B$14 -> 286 | U36: =MAX(0,T36-SUM(N36:S36)) -> 286 | V36: =_xlfn.MINIFS($B$3:$G$3,B36:G36,">0.005") -> 0 | W36: =IF(B36<=0.005,0,MIN(B36+H36,N36+IF(B$3=$V36,$U36,0))) -> 0 | X36: =IF(C36<=0.005,0,MIN(C36+I36,O36+IF(C$3=$V36,$U36,0))) -> 0 | Y36: =IF(D36<=0.005,0,MIN(D36+J36,P36+IF(D$3=$V36,$U36,0))) -> 0 | Z36: =IF(E36<=0.005,0,MIN(E36+K36,Q36+IF(E$3=$V36,$U36,0))) -> 0 | AA36: =IF(F36<=0.005,0,MIN(F36+L36,R36+IF(F$3=$V36,$U36,0))) -> 0 | AB36: =IF(G36<=0.005,0,MIN(G36+M36,S36+IF(G$3=$V36,$U36,0))) -> 0 | AC36: =MAX(0,B36+H36-W36) -> 0 | AD36: =MAX(0,C36+I36-X36) -> 0 | AE36: =MAX(0,D36+J36-Y36) -> 0 | AF36: =MAX(0,E36+K36-Z36) -> 0 | AG36: =MAX(0,F36+L36-AA36) -> 0 | AH36: =MAX(0,G36+M36-AB36) -> 0 | AI36: =SUM(H36:M36) -> 0 | AJ36: =SUM(AC36:AH36) -> 0
A37: 33 | B37: =AC36 -> 0 | C37: =AD36 -> 0 | D37: =AE36 -> 0 | E37: =AF36 -> 0 | F37: =AG36 -> 0 | G37: =AH36 -> 0 | H37: =B37*N(Debts!C7)/12 -> 0 | I37: =C37*N(Debts!C8)/12 -> 0 | J37: =D37*N(Debts!C9)/12 -> 0 | K37: =E37*N(Debts!C10)/12 -> 0 | L37: =F37*N(Debts!C11)/12 -> 0 | M37: =G37*N(Debts!C12)/12 -> 0 | N37: =MIN(B37+H37,N(Debts!D7)) -> 0 | O37: =MIN(C37+I37,N(Debts!D8)) -> 0 | P37: =MIN(D37+J37,N(Debts!D9)) -> 0 | Q37: =MIN(E37+K37,N(Debts!D10)) -> 0 | R37: =MIN(F37+L37,N(Debts!D11)) -> 0 | S37: =MIN(G37+M37,N(Debts!D12)) -> 0 | T37: =Debts!$B$14 -> 286 | U37: =MAX(0,T37-SUM(N37:S37)) -> 286 | V37: =_xlfn.MINIFS($B$3:$G$3,B37:G37,">0.005") -> 0 | W37: =IF(B37<=0.005,0,MIN(B37+H37,N37+IF(B$3=$V37,$U37,0))) -> 0 | X37: =IF(C37<=0.005,0,MIN(C37+I37,O37+IF(C$3=$V37,$U37,0))) -> 0 | Y37: =IF(D37<=0.005,0,MIN(D37+J37,P37+IF(D$3=$V37,$U37,0))) -> 0 | Z37: =IF(E37<=0.005,0,MIN(E37+K37,Q37+IF(E$3=$V37,$U37,0))) -> 0 | AA37: =IF(F37<=0.005,0,MIN(F37+L37,R37+IF(F$3=$V37,$U37,0))) -> 0 | AB37: =IF(G37<=0.005,0,MIN(G37+M37,S37+IF(G$3=$V37,$U37,0))) -> 0 | AC37: =MAX(0,B37+H37-W37) -> 0 | AD37: =MAX(0,C37+I37-X37) -> 0 | AE37: =MAX(0,D37+J37-Y37) -> 0 | AF37: =MAX(0,E37+K37-Z37) -> 0 | AG37: =MAX(0,F37+L37-AA37) -> 0 | AH37: =MAX(0,G37+M37-AB37) -> 0 | AI37: =SUM(H37:M37) -> 0 | AJ37: =SUM(AC37:AH37) -> 0
A38: 34 | B38: =AC37 -> 0 | C38: =AD37 -> 0 | D38: =AE37 -> 0 | E38: =AF37 -> 0 | F38: =AG37 -> 0 | G38: =AH37 -> 0 | H38: =B38*N(Debts!C7)/12 -> 0 | I38: =C38*N(Debts!C8)/12 -> 0 | J38: =D38*N(Debts!C9)/12 -> 0 | K38: =E38*N(Debts!C10)/12 -> 0 | L38: =F38*N(Debts!C11)/12 -> 0 | M38: =G38*N(Debts!C12)/12 -> 0 | N38: =MIN(B38+H38,N(Debts!D7)) -> 0 | O38: =MIN(C38+I38,N(Debts!D8)) -> 0 | P38: =MIN(D38+J38,N(Debts!D9)) -> 0 | Q38: =MIN(E38+K38,N(Debts!D10)) -> 0 | R38: =MIN(F38+L38,N(Debts!D11)) -> 0 | S38: =MIN(G38+M38,N(Debts!D12)) -> 0 | T38: =Debts!$B$14 -> 286 | U38: =MAX(0,T38-SUM(N38:S38)) -> 286 | V38: =_xlfn.MINIFS($B$3:$G$3,B38:G38,">0.005") -> 0 | W38: =IF(B38<=0.005,0,MIN(B38+H38,N38+IF(B$3=$V38,$U38,0))) -> 0 | X38: =IF(C38<=0.005,0,MIN(C38+I38,O38+IF(C$3=$V38,$U38,0))) -> 0 | Y38: =IF(D38<=0.005,0,MIN(D38+J38,P38+IF(D$3=$V38,$U38,0))) -> 0 | Z38: =IF(E38<=0.005,0,MIN(E38+K38,Q38+IF(E$3=$V38,$U38,0))) -> 0 | AA38: =IF(F38<=0.005,0,MIN(F38+L38,R38+IF(F$3=$V38,$U38,0))) -> 0 | AB38: =IF(G38<=0.005,0,MIN(G38+M38,S38+IF(G$3=$V38,$U38,0))) -> 0 | AC38: =MAX(0,B38+H38-W38) -> 0 | AD38: =MAX(0,C38+I38-X38) -> 0 | AE38: =MAX(0,D38+J38-Y38) -> 0 | AF38: =MAX(0,E38+K38-Z38) -> 0 | AG38: =MAX(0,F38+L38-AA38) -> 0 | AH38: =MAX(0,G38+M38-AB38) -> 0 | AI38: =SUM(H38:M38) -> 0 | AJ38: =SUM(AC38:AH38) -> 0
A39: 35 | B39: =AC38 -> 0 | C39: =AD38 -> 0 | D39: =AE38 -> 0 | E39: =AF38 -> 0 | F39: =AG38 -> 0 | G39: =AH38 -> 0 | H39: =B39*N(Debts!C7)/12 -> 0 | I39: =C39*N(Debts!C8)/12 -> 0 | J39: =D39*N(Debts!C9)/12 -> 0 | K39: =E39*N(Debts!C10)/12 -> 0 | L39: =F39*N(Debts!C11)/12 -> 0 | M39: =G39*N(Debts!C12)/12 -> 0 | N39: =MIN(B39+H39,N(Debts!D7)) -> 0 | O39: =MIN(C39+I39,N(Debts!D8)) -> 0 | P39: =MIN(D39+J39,N(Debts!D9)) -> 0 | Q39: =MIN(E39+K39,N(Debts!D10)) -> 0 | R39: =MIN(F39+L39,N(Debts!D11)) -> 0 | S39: =MIN(G39+M39,N(Debts!D12)) -> 0 | T39: =Debts!$B$14 -> 286 | U39: =MAX(0,T39-SUM(N39:S39)) -> 286 | V39: =_xlfn.MINIFS($B$3:$G$3,B39:G39,">0.005") -> 0 | W39: =IF(B39<=0.005,0,MIN(B39+H39,N39+IF(B$3=$V39,$U39,0))) -> 0 | X39: =IF(C39<=0.005,0,MIN(C39+I39,O39+IF(C$3=$V39,$U39,0))) -> 0 | Y39: =IF(D39<=0.005,0,MIN(D39+J39,P39+IF(D$3=$V39,$U39,0))) -> 0 | Z39: =IF(E39<=0.005,0,MIN(E39+K39,Q39+IF(E$3=$V39,$U39,0))) -> 0 | AA39: =IF(F39<=0.005,0,MIN(F39+L39,R39+IF(F$3=$V39,$U39,0))) -> 0 | AB39: =IF(G39<=0.005,0,MIN(G39+M39,S39+IF(G$3=$V39,$U39,0))) -> 0 | AC39: =MAX(0,B39+H39-W39) -> 0 | AD39: =MAX(0,C39+I39-X39) -> 0 | AE39: =MAX(0,D39+J39-Y39) -> 0 | AF39: =MAX(0,E39+K39-Z39) -> 0 | AG39: =MAX(0,F39+L39-AA39) -> 0 | AH39: =MAX(0,G39+M39-AB39) -> 0 | AI39: =SUM(H39:M39) -> 0 | AJ39: =SUM(AC39:AH39) -> 0
A40: 36 | B40: =AC39 -> 0 | C40: =AD39 -> 0 | D40: =AE39 -> 0 | E40: =AF39 -> 0 | F40: =AG39 -> 0 | G40: =AH39 -> 0 | H40: =B40*N(Debts!C7)/12 -> 0 | I40: =C40*N(Debts!C8)/12 -> 0 | J40: =D40*N(Debts!C9)/12 -> 0 | K40: =E40*N(Debts!C10)/12 -> 0 | L40: =F40*N(Debts!C11)/12 -> 0 | M40: =G40*N(Debts!C12)/12 -> 0 | N40: =MIN(B40+H40,N(Debts!D7)) -> 0 | O40: =MIN(C40+I40,N(Debts!D8)) -> 0 | P40: =MIN(D40+J40,N(Debts!D9)) -> 0 | Q40: =MIN(E40+K40,N(Debts!D10)) -> 0 | R40: =MIN(F40+L40,N(Debts!D11)) -> 0 | S40: =MIN(G40+M40,N(Debts!D12)) -> 0 | T40: =Debts!$B$14 -> 286 | U40: =MAX(0,T40-SUM(N40:S40)) -> 286 | V40: =_xlfn.MINIFS($B$3:$G$3,B40:G40,">0.005") -> 0 | W40: =IF(B40<=0.005,0,MIN(B40+H40,N40+IF(B$3=$V40,$U40,0))) -> 0 | X40: =IF(C40<=0.005,0,MIN(C40+I40,O40+IF(C$3=$V40,$U40,0))) -> 0 | Y40: =IF(D40<=0.005,0,MIN(D40+J40,P40+IF(D$3=$V40,$U40,0))) -> 0 | Z40: =IF(E40<=0.005,0,MIN(E40+K40,Q40+IF(E$3=$V40,$U40,0))) -> 0 | AA40: =IF(F40<=0.005,0,MIN(F40+L40,R40+IF(F$3=$V40,$U40,0))) -> 0 | AB40: =IF(G40<=0.005,0,MIN(G40+M40,S40+IF(G$3=$V40,$U40,0))) -> 0 | AC40: =MAX(0,B40+H40-W40) -> 0 | AD40: =MAX(0,C40+I40-X40) -> 0 | AE40: =MAX(0,D40+J40-Y40) -> 0 | AF40: =MAX(0,E40+K40-Z40) -> 0 | AG40: =MAX(0,F40+L40-AA40) -> 0 | AH40: =MAX(0,G40+M40-AB40) -> 0 | AI40: =SUM(H40:M40) -> 0 | AJ40: =SUM(AC40:AH40) -> 0
...
